Workbook
Name GANANCIA_DIVISA: 'PARÁMETROS'!$B$5
Name GANANCIA_BCV: 'PARÁMETROS'!$B$6
Name DESC_TEAM: 'PARÁMETROS'!$B$7
Name DESC_REVENDEDOR: 'PARÁMETROS'!$B$8

Sheet PARÁMETROS
A1: PARÁMETROS DEL SISTEMA
A2: Editá solo estas celdas amarillas: todas las listas de precios se recalculan solas. Los dos primeros valores son la GANANCIA SOBRE EL COSTO, no el precio final.
A4: Nombre definido | B4: Valor | C4: Formato | D4: Qué controla | E4: Equivale a
A5: GANANCIA_DIVISA | B5: 0.7 | C5: % | D5: Ganancia sobre el COSTO cuando el cliente paga en divisa o USDT (PRECIOS PERF TOP QUALITY) | E5: precio = costo × 1,70
A6: GANANCIA_BCV | B6: 1.2 | C6: % | D6: Ganancia sobre el COSTO cuando el cliente paga a tasa BCV (PRECIOS PERF TOP QUALITY) | E6: precio = costo × 2,20
A7: DESC_TEAM | B7: 0.25 | C7: % | D7: Descuento sobre el precio original para el team (PRECIOS PERF ORIGINALES) | E7: precio = original × 0,75
A8: DESC_REVENDEDOR | B8: 0.15 | C8: % | D8: Descuento sobre el precio original para revendedores (PRECIOS PERF ORIGINALES) | E8: precio = original × 0,85

Sheet CONTROL
A1: CONTROL DE PAGOS Y COBRANZA
F2: PAGO 1 | I2: PAGO 2 | L2: PAGO 3
A3: FECHA VENTA | B3: CLIENTE | C3: VENDEDOR | D3: PRODUCTO | E3: PRECIO TOTAL ($) | F3: MONTO Bs P1 | G3: FECHA P1 | H3: REFERENCIA P1 | I3: MONTO Bs P2 | J3: FECHA P2 | K3: REFERENCIA P2 | L3: MONTO Bs P3 | M3: FECHA P3 | N3: REFERENCIA P3 | O3: ESTATUS | P3: TOTAL ABONADO Bs | Q3: NOTAS | S3: RESUMEN (dinámico)
A4: 46200 | B4: Cristhian | C4: Gregory | D4: Very Good Girl | E4: 24 | F4: 7466.56 | G4: 46200 | H4: 5863 | I4: 7835.67 | J4: 46207 | K4: 9442 | O4: YA PAGO | P4: =IF(COUNT(F4,I4,L4)=0,"",SUM(F4,I4,L4)) | S4: Operaciones registradas | T4: =COUNT(A:A)
A5: 46200 | B5: Amarista | C5: Gregory | D5: Khamrah Qahwa | E5: 42 | F5: 13066.48 | G5: 46200 | H5: 6585 | I5: 14903.56 | J5: 46214 | K5: 5675 | O5: YA PAGO | P5: =IF(COUNT(F5,I5,L5)=0,"",SUM(F5,I5,L5)) | S5: Total en Ventas ($) | T5: =SUM(E:E)
A6: 46201 | B6: Ángel | C6: Gregory | D6: Bharara King | E6: 42 | F6: 13066.48 | G6: 46201 | H6: 5135 | I6: 15679.22 | J6: 46235 | K6: 7366 | O6: YA PAGO | P6: =IF(COUNT(F6,I6,L6)=0,"",SUM(F6,I6,L6)) | S6: Total abonado en Bs | T6: =SUM(P:P)
A7: 46202 | B7: Ricardo | C7: Gregory | D7: Universe | E7: 42 | F7: 11823 | G7: 46202 | H7: 9373 | I7: 8730 | J7: 46219 | K7: 1008 | L7: 8307 | M7: 46239 | N7: 542 | O7: YA PAGO | P7: =IF(COUNT(F7,I7,L7)=0,"",SUM(F7,I7,L7)) | S7: · Pago 1 (Bs) | T7: =SUM(F:F)
A8: 46206 | B8: Norelvis | C8: Gregory | D8: Cloud | E8: 30 | F8: 9794.59 | G8: 46206 | H8: 8447 | I8: 10645.4 | J8: 46215 | K8: 4494 | O8: YA PAGO | P8: =IF(COUNT(F8,I8,L8)=0,"",SUM(F8,I8,L8)) | S8: · Pago 2 (Bs) | T8: =SUM(I:I)
A9: 46207 | B9: Anderson | C9: Gregory | D9: 212 Vip | E9: 22 | F9: 4580 | G9: 46207 | H9: 172 | I9: 5100 | J9: 46218 | K9: 2830 | L9: 5910 | M9: 46231 | N9: 5001 | O9: YA PAGO | P9: =IF(COUNT(F9,I9,L9)=0,"",SUM(F9,I9,L9)) | S9: · Pago 3 (Bs) | T9: =SUM(L:L)
A10: 46207 | B10: Marbella | C10: Gregory | D10: Yara Moi | E10: 30 | F10: 13341 | G10: 46207 | H10: 1469 | I10: 7420 | J10: 46228 | K10: 6675 | O10: YA PAGO | P10: =IF(COUNT(F10,I10,L10)=0,"",SUM(F10,I10,L10)) | Q10: Fecha pago 3 anotada como «listo» | S10: Operaciones YA PAGO | T10: =COUNTIF(O:O,"YA PAGO")
A11: 46207 | B11: Polanco | C11: Gregory | D11: Club de Nuit | E11: 30 | F11: 9794.59 | G11: 46207 | H11: 9023 | I11: 11068.22 | J11: 46228 | K11: 2736 | O11: YA PAGO | P11: =IF(COUNT(F11,I11,L11)=0,"",SUM(F11,I11,L11)) | Q11: Fecha pago 3 anotada como «listo» | S11: Operaciones PENDIENTE | T11: =COUNTIF(O:O,"PENDIENTE*")
A12: 46214 | B12: Polanco | C12: Gregory | D12: Honor y Glory | E12: 35 | F12: 14193.87 | G12: 46214 | H12: 5460 | I12: 11199.45 | J12: 46236 | K12: 2165 | P12: =IF(COUNT(F12,I12,L12)=0,"",SUM(F12,I12,L12)) | S12: Operaciones sin estatus | T12: =SUMPRODUCT(($A$4:$A$39<>"")*($O$4:$O$39=""))
A13: 46215 | B13: Llovera | C13: Gregory | D13: Eros Men | E13: 24 | F13: 17000 | G13: 46215 | H13: 1911 | O13: YA PAGO | P13: =IF(COUNT(F13,I13,L13)=0,"",SUM(F13,I13,L13)) | S13: Operaciones sin ningún abono | T13: =SUMPRODUCT(($A$4:$A$39<>"")*($F$4:$F$39="")*($I$4:$I$39="")*($L$4:$L$39=""))
A14: 46218 | B14: Belisario | C14: Gregory | D14: Club de Nuit Urban | E14: 30 | F14: 10886.21 | G14: 46218 | H14: 7099 | O14: PENDIENTE | P14: =IF(COUNT(F14,I14,L14)=0,"",SUM(F14,I14,L14))
A15: 46219 | B15: Fernanda | C15: Gregory | D15: Yara Fem | E15: 30 | F15: 14549.02 | G15: 46219 | H15: 7014 | I15: 3733.15 | J15: 46236 | K15: 9323 | O15: PENDIENTE | P15: =IF(COUNT(F15,I15,L15)=0,"",SUM(F15,I15,L15)) | S15: Total Divisas Pagadas ($) — captura manual | T15: 306
A16: 46220 | B16: Cristhian | C16: Gregory | D16: Aqua Dubai | E16: 34 | F16: 10645.4 | G16: 46213 | H16: 8770 | I16: 10987.18 | J16: 46220 | K16: 546 | L16: 2951.53 | M16: 46227 | N16: 9686 | O16: YA PAGO | P16: =IF(COUNT(F16,I16,L16)=0,"",SUM(F16,I16,L16)) | S16: No existe columna de abonos en $ en la hoja, así que este total sigue siendo un valor escrito a mano (venía del original).
A17: 46192 | B17: Ivana | C17: Gregory | D17: La Bomba | E17: 30 | O17: PENDIENTE (SIN ABONOS) | P17: =IF(COUNT(F17,I17,L17)=0,"",SUM(F17,I17,L17))
A18: 46199 | B18: Reinel | C18: Hidelberg | D18: 212 NYC | E18: 24 | F18: 18183 | G18: 46244 | H18: 4795 | P18: =IF(COUNT(F18,I18,L18)=0,"",SUM(F18,I18,L18)) | S18: Valores sueltos hallados en C64/D64 del archivo original (estaban dentro de la fila de totales, sin etiqueta):
A19: 46220 | B19: Mirleidy | C19: Gregory | D19: 360 | E19: 12 | G19: 46236 | P19: =IF(COUNT(F19,I19,L19)=0,"",SUM(F19,I19,L19)) | Q19: Precio anotado como «12 MY» | Pago 1 anotado como «12 EFECTIVO» (no es un monto en Bs) | S19: C64 | T19: 260
A20: 46220 | B20: Mirleidy | C20: Gregory | D20: ASAD BORBOM | E20: 16 | G20: 46236 | P20: =IF(COUNT(F20,I20,L20)=0,"",SUM(F20,I20,L20)) | Q20: Precio anotado como «16 MY» | Pago 1 anotado como «16 EFECTIVO» (no es un monto en Bs) | S20: D64 | T20: 100
A21: 46232 | B21: Polanco | C21: Gregory | D21: TOMMY | E21: 24 | F21: 8854.58 | G21: 46231 | H21: 1826 | I21: 8985.44 | J21: 46237 | K21: 5170 | P21: =IF(COUNT(F21,I21,L21)=0,"",SUM(F21,I21,L21))
A22: 46232 | B22: Belisario | C22: Gregory | D22: BAD BOY | E22: 24 | P22: =IF(COUNT(F22,I22,L22)=0,"",SUM(F22,I22,L22))
A23: 46233 | B23: Anderson | C23: Gregory | D23: AQUA DI GIO | E23: 22 | F23: 5400 | G23: 46250 | H23: 2265 | P23: =IF(COUNT(F23,I23,L23)=0,"",SUM(F23,I23,L23))
A24: 46236 | B24: Adolfito | C24: Gregory | D24: SCANDAL | E24: 22 | F24: 8212.93 | G24: 46236 | H24: 1103 | P24: =IF(COUNT(F24,I24,L24)=0,"",SUM(F24,I24,L24))
A25: 46236 | B25: Rafael | C25: Gregory | D25: INVICTUS | E25: 22 | F25: 5226.34 | G25: 46236 | H25: 666 | I25: 5398 | J25: 46249 | K25: 8343 | P25: =IF(COUNT(F25,I25,L25)=0,"",SUM(F25,I25,L25))
A26: 46061 | B26: Ricardo | C26: Gregory | D26: AQUA DI GIO | E26: 24 | P26: =IF(COUNT(F26,I26,L26)=0,"",SUM(F26,I26,L26))
A27: 46061 | B27: Melany | C27: Gregory | D27: CLOUD | E27: 24 | P27: =IF(COUNT(F27,I27,L27)=0,"",SUM(F27,I27,L27))
A28: 46061 | B28: Gregor | C28: Gregor | D28: BHARARA BLUE | E28: 18 | P28: =IF(COUNT(F28,I28,L28)=0,"",SUM(F28,I28,L28)) | Q28: Precio anotado como «18 GM»
A29: 46061 | B29: Hidelberg | C29: Hidelberg | D29: TOMMY | E29: 12 | P29: =IF(COUNT(F29,I29,L29)=0,"",SUM(F29,I29,L29)) | Q29: Precio anotado como «12 GM»
A30: 46061 | B30: Juan Herrade | C30: Gregor | D30: Sauvage Dior | E30: 22 | P30: =IF(COUNT(F30,I30,L30)=0,"",SUM(F30,I30,L30))
A31: 46061 | B31: Juan Herrade | C31: Gregor | D31: Victorinox swis army | E31: 22 | P31: =IF(COUNT(F31,I31,L31)=0,"",SUM(F31,I31,L31))
A32: 46061 | B32: Ricardo Palacios | C32: Gregor | D32: Eros Flame | E32: 22 | P32: =IF(COUNT(F32,I32,L32)=0,"",SUM(F32,I32,L32))
A33: 46061 | B33: Ricardo Palacios | C33: Gregor | D33: Mandarin Sky | E33: 22 | P33: =IF(COUNT(F33,I33,L33)=0,"",SUM(F33,I33,L33))
A34: 46244 | B34: Jeferson Mejias | C34: Hidelberg | D34: BHARARA KING | E34: 42 | P34: =IF(COUNT(F34,I34,L34)=0,"",SUM(F34,I34,L34))
A35: 46245 | B35: Apostol | C35: Gregory | D35: Sauvage Dior | E35: 24 | F35: 9252.86 | G35: 46249 | H35: 7526 | P35: =IF(COUNT(F35,I35,L35)=0,"",SUM(F35,I35,L35))
A36: 46244 | B36: Hade Mirleidy | C36: Gregor | D36: YARA ELIXIR | E36: 24 | P36: =IF(COUNT(F36,I36,L36)=0,"",SUM(F36,I36,L36))
A37: 46244 | B37: Luis Sequera | C37: Gregor | D37: Mandarin Sky | E37: 31 | P37: =IF(COUNT(F37,I37,L37)=0,"",SUM(F37,I37,L37))
A38: 46246 | B38: Ricardo Gomez | C38: Gregory | D38: CLUD DE NUIT INTENSE | E38: 19 | F38: 8356 | G38: 46246 | H38: 4657 | P38: =IF(COUNT(F38,I38,L38)=0,"",SUM(F38,I38,L38)) | Q38: Precio anotado como «19 usdt P.M»
A39: 46247 | B39: Cristhian Gonzales | C39: Gregory | D39: 9PM REBEL ORIGINAL | E39: 70 | P39: =IF(COUNT(F39,I39,L39)=0,"",SUM(F39,I39,L39))

Sheet VENTAS
A1: REGISTRO DE VENTAS
A3: N° OPERACIÓN | B3: PRODUCTO | C3: CLIENTE | D3: VENDEDOR | E3: PRECIO VENTA ($) | F3: COSTO ($) | G3: GANANCIA ($) | H3: MARGEN | I3: MONEDA | J3: ABONADO ($) | K3: DEUDA ($) | L3: NOTAS | N3: RESUMEN (dinámico)
A4: 1 | B4: Yara Fem | C4: Fernanda | D4: Gregory | E4: 30 | F4: 13 | G4: =IF(COUNT(E4:F4)<2,"",E4-F4) | H4: =IF(OR(G4="",E4=""),"",G4/E4) | I4: BCV | J4: =SUMIFS('REGISTRO DE CUOTAS'!$F:$F,'REGISTRO DE CUOTAS'!$D:$D,$C4,'REGISTRO DE CUOTAS'!$E:$E,$B4) | K4: =IF(E4="","",E4-J4) | N4: Ventas registradas | O4: =COUNTA($B$4:$B$45)
A5: 2 | B5: Bharara King | C5: Ángel | D5: Gregory | E5: 42 | F5: 20 | G5: =IF(COUNT(E5:F5)<2,"",E5-F5) | H5: =IF(OR(G5="",E5=""),"",G5/E5) | I5: BCV | J5: =SUMIFS('REGISTRO DE CUOTAS'!$F:$F,'REGISTRO DE CUOTAS'!$D:$D,$C5,'REGISTRO DE CUOTAS'!$E:$E,$B5) | K5: =IF(E5="","",E5-J5) | N5: Total Ventas ($) | O5: =SUM(E:E)
A6: 3 | B6: Khamarah Qahwa | C6: Amarista | D6: Gregory | E6: 42 | F6: 20 | G6: =IF(COUNT(E6:F6)<2,"",E6-F6) | H6: =IF(OR(G6="",E6=""),"",G6/E6) | I6: BCV | J6: =SUMIFS('REGISTRO DE CUOTAS'!$F:$F,'REGISTRO DE CUOTAS'!$D:$D,$C6,'REGISTRO DE CUOTAS'!$E:$E,$B6) | K6: =IF(E6="","",E6-J6) | N6: Costo Total ($) | O6: =SUM(F:F)
A7: 4 | B7: Universe | C7: Ricardo | D7: Gregory | E7: 42 | F7: 20 | G7: =IF(COUNT(E7:F7)<2,"",E7-F7) | H7: =IF(OR(G7="",E7=""),"",G7/E7) | I7: BCV | J7: =SUMIFS('REGISTRO DE CUOTAS'!$F:$F,'REGISTRO DE CUOTAS'!$D:$D,$C7,'REGISTRO DE CUOTAS'!$E:$E,$B7) | K7: =IF(E7="","",E7-J7) | N7: Ganancia Total ($) | O7: =SUM(G:G)
A8: 5 | B8: Club de Nuit Urban Elixir | C8: Belisario | D8: Gregory | E8: 30 | F8: 13 | G8: =IF(COUNT(E8:F8)<2,"",E8-F8) | H8: =IF(OR(G8="",E8=""),"",G8/E8) | I8: BCV | J8: =SUMIFS('REGISTRO DE CUOTAS'!$F:$F,'REGISTRO DE CUOTAS'!$D:$D,$C8,'REGISTRO DE CUOTAS'!$E:$E,$B8) | K8: =IF(E8="","",E8-J8) | N8: Margen promedio | O8: =IF(SUM(E:E)=0,"",SUM(G:G)/SUM(E:E))
A9: 6 | B9: Yara Moi | C9: Marbella | D9: Gregory | E9: 30 | F9: 13 | G9: =IF(COUNT(E9:F9)<2,"",E9-F9) | H9: =IF(OR(G9="",E9=""),"",G9/E9) | I9: BCV | J9: =SUMIFS('REGISTRO DE CUOTAS'!$F:$F,'REGISTRO DE CUOTAS'!$D:$D,$C9,'REGISTRO DE CUOTAS'!$E:$E,$B9) | K9: =IF(E9="","",E9-J9) | N9: Total Abonado ($) | O9: =SUM(J:J)
A10: 7 | B10: Very Good Grul | C10: Cristihan | D10: Gregory | E10: 24 | F10: 9.5 | G10: =IF(COUNT(E10:F10)<2,"",E10-F10) | H10: =IF(OR(G10="",E10=""),"",G10/E10) | I10: BCV | J10: =SUMIFS('REGISTRO DE CUOTAS'!$F:$F,'REGISTRO DE CUOTAS'!$D:$D,$C10,'REGISTRO DE CUOTAS'!$E:$E,$B10) | K10: =IF(E10="","",E10-J10) | N10: Total por Cobrar ($) | O10: =SUM(K:K)
A11: 8 | B11: Honor y glory | C11: Polanco | D11: Gregory | E11: 35 | F11: 12 | G11: =IF(COUNT(E11:F11)<2,"",E11-F11) | H11: =IF(OR(G11="",E11=""),"",G11/E11) | I11: BCV | J11: =SUMIFS('REGISTRO DE CUOTAS'!$F:$F,'REGISTRO DE CUOTAS'!$D:$D,$C11,'REGISTRO DE CUOTAS'!$E:$E,$B11) | K11: =IF(E11="","",E11-J11) | N11: Ventas con pérdida | O11: =COUNTIF(G:G,"<0")
A12: 9 | B12: cloud | C12: Norelvis | D12: Gregory | E12: 30 | F12: 12 | G12: =IF(COUNT(E12:F12)<2,"",E12-F12) | H12: =IF(OR(G12="",E12=""),"",G12/E12) | I12: BCV | J12: =SUMIFS('REGISTRO DE CUOTAS'!$F:$F,'REGISTRO DE CUOTAS'!$D:$D,$C12,'REGISTRO DE CUOTAS'!$E:$E,$B12) | K12: =IF(E12="","",E12-J12)
B13: la bomba | C13: Ivana | D13: Gregory | E13: 30 | F13: 17 | G13: =IF(COUNT(E13:F13)<2,"",E13-F13) | H13: =IF(OR(G13="",E13=""),"",G13/E13) | I13: BCV | J13: =SUMIFS('REGISTRO DE CUOTAS'!$F:$F,'REGISTRO DE CUOTAS'!$D:$D,$C13,'REGISTRO DE CUOTAS'!$E:$E,$B13) | K13: =IF(E13="","",E13-J13) | N13: «Total Abonado» sale de la hoja REGISTRO DE CUOTAS, hoy vacía: hasta que se carguen los abonos, la deuda mostrada es el precio completo.
B14: Aqua Dubai | C14: Cristhian | D14: Gregory | E14: 34 | F14: 18 | G14: =IF(COUNT(E14:F14)<2,"",E14-F14) | H14: =IF(OR(G14="",E14=""),"",G14/E14) | I14: BCV | J14: =SUMIFS('REGISTRO DE CUOTAS'!$F:$F,'REGISTRO DE CUOTAS'!$D:$D,$C14,'REGISTRO DE CUOTAS'!$E:$E,$B14) | K14: =IF(E14="","",E14-J14)
A15: 10 | B15: 212Vip | C15: Anderson | D15: Gregory | E15: 9.5 | F15: 22 | G15: =IF(COUNT(E15:F15)<2,"",E15-F15) | H15: =IF(OR(G15="",E15=""),"",G15/E15) | I15: BCV | J15: =SUMIFS('REGISTRO DE CUOTAS'!$F:$F,'REGISTRO DE CUOTAS'!$D:$D,$C15,'REGISTRO DE CUOTAS'!$E:$E,$B15) | K15: =IF(E15="","",E15-J15)
B16: Club de Nuit | C16: Polanco | D16: Gregory | E16: 30 | F16: 51 | G16: =IF(COUNT(E16:F16)<2,"",E16-F16) | H16: =IF(OR(G16="",E16=""),"",G16/E16) | I16: BCV | J16: =SUMIFS('REGISTRO DE CUOTAS'!$F:$F,'REGISTRO DE CUOTAS'!$D:$D,$C16,'REGISTRO DE CUOTAS'!$E:$E,$B16) | K16: =IF(E16="","",E16-J16)
A17: 11 | B17: 212 NYC | C17: Reinel | D17: Hidelberg | E17: 24 | F17: 12 | G17: =IF(COUNT(E17:F17)<2,"",E17-F17) | H17: =IF(OR(G17="",E17=""),"",G17/E17) | I17: BCV | J17: =SUMIFS('REGISTRO DE CUOTAS'!$F:$F,'REGISTRO DE CUOTAS'!$D:$D,$C17,'REGISTRO DE CUOTAS'!$E:$E,$B17) | K17: =IF(E17="","",E17-J17)
A18: 12 | B18: EROS MEN VERSACHE | C18: Llovera | D18: Gregory | E18: 24 | F18: 9.5 | G18: =IF(COUNT(E18:F18)<2,"",E18-F18) | H18: =IF(OR(G18="",E18=""),"",G18/E18) | J18: =SUMIFS('REGISTRO DE CUOTAS'!$F:$F,'REGISTRO DE CUOTAS'!$D:$D,$C18,'REGISTRO DE CUOTAS'!$E:$E,$B18) | K18: =IF(E18="","",E18-J18)
A19: 13 | B19: 360 | C19: Mirleidy | D19: Gregory | E19: 12 | F19: 9.5 | G19: =IF(COUNT(E19:F19)<2,"",E19-F19) | H19: =IF(OR(G19="",E19=""),"",G19/E19) | J19: =SUMIFS('REGISTRO DE CUOTAS'!$F:$F,'REGISTRO DE CUOTAS'!$D:$D,$C19,'REGISTRO DE CUOTAS'!$E:$E,$B19) | K19: =IF(E19="","",E19-J19)
B20: ASAD BORBOM | C20: Mirleidy | D20: Gregory | E20: 16 | F20: 13 | G20: =IF(COUNT(E20:F20)<2,"",E20-F20) | H20: =IF(OR(G20="",E20=""),"",G20/E20) | J20: =SUMIFS('REGISTRO DE CUOTAS'!$F:$F,'REGISTRO DE CUOTAS'!$D:$D,$C20,'REGISTRO DE CUOTAS'!$E:$E,$B20) | K20: =IF(E20="","",E20-J20)
B21: TOMMY | C21: Polanco | D21: Gregory | E21: 24 | F21: 11 | G21: =IF(COUNT(E21:F21)<2,"",E21-F21) | H21: =IF(OR(G21="",E21=""),"",G21/E21) | J21: =SUMIFS('REGISTRO DE CUOTAS'!$F:$F,'REGISTRO DE CUOTAS'!$D:$D,$C21,'REGISTRO DE CUOTAS'!$E:$E,$B21) | K21: =IF(E21="","",E21-J21)
B22: BAD BOY | C22: Belisario | D22: Gregory | E22: 24 | F22: 9.5 | G22: =IF(COUNT(E22:F22)<2,"",E22-F22) | H22: =IF(OR(G22="",E22=""),"",G22/E22) | J22: =SUMIFS('REGISTRO DE CUOTAS'!$F:$F,'REGISTRO DE CUOTAS'!$D:$D,$C22,'REGISTRO DE CUOTAS'!$E:$E,$B22) | K22: =IF(E22="","",E22-J22)
B23: AQUA DI GIO | C23: Anderson | D23: Gregory | E23: 22 | F23: 9.5 | G23: =IF(COUNT(E23:F23)<2,"",E23-F23) | H23: =IF(OR(G23="",E23=""),"",G23/E23) | J23: =SUMIFS('REGISTRO DE CUOTAS'!$F:$F,'REGISTRO DE CUOTAS'!$D:$D,$C23,'REGISTRO DE CUOTAS'!$E:$E,$B23) | K23: =IF(E23="","",E23-J23)
A24: 14 | B24: SCANDAL | C24: Adolfito | D24: Gregory | E24: 22 | F24: 9.5 | G24: =IF(COUNT(E24:F24)<2,"",E24-F24) | H24: =IF(OR(G24="",E24=""),"",G24/E24) | J24: =SUMIFS('REGISTRO DE CUOTAS'!$F:$F,'REGISTRO DE CUOTAS'!$D:$D,$C24,'REGISTRO DE CUOTAS'!$E:$E,$B24) | K24: =IF(E24="","",E24-J24)
A25: 15 | B25: INVICTUS | C25: Rafael | D25: Gregory | E25: 22 | F25: 9.5 | G25: =IF(COUNT(E25:F25)<2,"",E25-F25) | H25: =IF(OR(G25="",E25=""),"",G25/E25) | J25: =SUMIFS('REGISTRO DE CUOTAS'!$F:$F,'REGISTRO DE CUOTAS'!$D:$D,$C25,'REGISTRO DE CUOTAS'!$E:$E,$B25) | K25: =IF(E25="","",E25-J25)
B26: AQUA DI GIO | C26: Ricardo | D26: Gregory | E26: 24 | F26: 12 | G26: =IF(COUNT(E26:F26)<2,"",E26-F26) | H26: =IF(OR(G26="",E26=""),"",G26/E26) | J26: =SUMIFS('REGISTRO DE CUOTAS'!$F:$F,'REGISTRO DE CUOTAS'!$D:$D,$C26,'REGISTRO DE CUOTAS'!$E:$E,$B26) | K26: =IF(E26="","",E26-J26)
A27: 16 | B27: CLOUD | C27: Melany | D27: Gregory | E27: 24 | F27: 12 | G27: =IF(COUNT(E27:F27)<2,"",E27-F27) | H27: =IF(OR(G27="",E27=""),"",G27/E27) | J27: =SUMIFS('REGISTRO DE CUOTAS'!$F:$F,'REGISTRO DE CUOTAS'!$D:$D,$C27,'REGISTRO DE CUOTAS'!$E:$E,$B27) | K27: =IF(E27="","",E27-J27)
B28: BHARARA BLUE | C28: Gregor | D28: Gregor | E28: 18 | F28: 18 | G28: =IF(COUNT(E28:F28)<2,"",E28-F28) | H28: =IF(OR(G28="",E28=""),"",G28/E28) | I28: GM | J28: =SUMIFS('REGISTRO DE CUOTAS'!$F:$F,'REGISTRO DE CUOTAS'!$D:$D,$C28,'REGISTRO DE CUOTAS'!$E:$E,$B28) | K28: =IF(E28="","",E28-J28) | L28: Precio anotado como «18.GM»
B29: TOMMY | C29: Hidelberg | D29: Hidelberg | E29: 12 | F29: 12 | G29: =IF(COUNT(E29:F29)<2,"",E29-F29) | H29: =IF(OR(G29="",E29=""),"",G29/E29) | I29: GM | J29: =SUMIFS('REGISTRO DE CUOTAS'!$F:$F,'REGISTRO DE CUOTAS'!$D:$D,$C29,'REGISTRO DE CUOTAS'!$E:$E,$B29) | K29: =IF(E29="","",E29-J29) | L29: Precio anotado como «12.GM»
A30: 17 | B30: Sauvage Dior | C30: Juan Herrade | D30: Gregory | E30: 22 | F30: 12 | G30: =IF(COUNT(E30:F30)<2,"",E30-F30) | H30: =IF(OR(G30="",E30=""),"",G30/E30) | J30: =SUMIFS('REGISTRO DE CUOTAS'!$F:$F,'REGISTRO DE CUOTAS'!$D:$D,$C30,'REGISTRO DE CUOTAS'!$E:$E,$B30) | K30: =IF(E30="","",E30-J30)
B31: Victorinox swis army | C31: Juan Herrade | D31: Gregory | E31: 22 | F31: 9.5 | G31: =IF(COUNT(E31:F31)<2,"",E31-F31) | H31: =IF(OR(G31="",E31=""),"",G31/E31) | J31: =SUMIFS('REGISTRO DE CUOTAS'!$F:$F,'REGISTRO DE CUOTAS'!$D:$D,$C31,'REGISTRO DE CUOTAS'!$E:$E,$B31) | K31: =IF(E31="","",E31-J31)
A32: 18 | B32: Eros Flame | C32: Ricardo Palacios | D32: Gregor | E32: 22 | F32: 12 | G32: =IF(COUNT(E32:F32)<2,"",E32-F32) | H32: =IF(OR(G32="",E32=""),"",G32/E32) | J32: =SUMIFS('REGISTRO DE CUOTAS'!$F:$F,'REGISTRO DE CUOTAS'!$D:$D,$C32,'REGISTRO DE CUOTAS'!$E:$E,$B32) | K32: =IF(E32="","",E32-J32)
B33: Mandarin Sky | C33: Ricardo Palacios | D33: Gregor | E33: 22 | F33: 15 | G33: =IF(COUNT(E33:F33)<2,"",E33-F33) | H33: =IF(OR(G33="",E33=""),"",G33/E33) | J33: =SUMIFS('REGISTRO DE CUOTAS'!$F:$F,'REGISTRO DE CUOTAS'!$D:$D,$C33,'REGISTRO DE CUOTAS'!$E:$E,$B33) | K33: =IF(E33="","",E33-J33)
A34: 19 | B34: BHARARA KING | C34: Jeferson Mejias | D34: Hidelberg | E34: 42 | F34: 20 | G34: =IF(COUNT(E34:F34)<2,"",E34-F34) | H34: =IF(OR(G34="",E34=""),"",G34/E34) | J34: =SUMIFS('REGISTRO DE CUOTAS'!$F:$F,'REGISTRO DE CUOTAS'!$D:$D,$C34,'REGISTRO DE CUOTAS'!$E:$E,$B34) | K34: =IF(E34="","",E34-J34)
A35: 20 | B35: Sauvage Dior | C35: Apostol | D35: Gregory | E35: 24 | F35: 12 | G35: =IF(COUNT(E35:F35)<2,"",E35-F35) | H35: =IF(OR(G35="",E35=""),"",G35/E35) | J35: =SUMIFS('REGISTRO DE CUOTAS'!$F:$F,'REGISTRO DE CUOTAS'!$D:$D,$C35,'REGISTRO DE CUOTAS'!$E:$E,$B35) | K35: =IF(E35="","",E35-J35)
B36: YARA ELIXIR | C36: Hade Mirleidy | D36: Gregor | E36: 24 | F36: 12 | G36: =IF(COUNT(E36:F36)<2,"",E36-F36) | H36: =IF(OR(G36="",E36=""),"",G36/E36) | J36: =SUMIFS('REGISTRO DE CUOTAS'!$F:$F,'REGISTRO DE CUOTAS'!$D:$D,$C36,'REGISTRO DE CUOTAS'!$E:$E,$B36) | K36: =IF(E36="","",E36-J36)
A37: 21 | B37: Mandarin Sky | C37: Luis Sequera | D37: Gregor | E37: 32 | F37: 15 | G37: =IF(COUNT(E37:F37)<2,"",E37-F37) | H37: =IF(OR(G37="",E37=""),"",G37/E37) | J37: =SUMIFS('REGISTRO DE CUOTAS'!$F:$F,'REGISTRO DE CUOTAS'!$D:$D,$C37,'REGISTRO DE CUOTAS'!$E:$E,$B37) | K37: =IF(E37="","",E37-J37)
B38: CLUD DE NUIT INTENSE | C38: Ricardo Gomez | D38: Gregory | E38: 19 | F38: 15 | G38: =IF(COUNT(E38:F38)<2,"",E38-F38) | H38: =IF(OR(G38="",E38=""),"",G38/E38) | I38: usdt P.M | J38: =SUMIFS('REGISTRO DE CUOTAS'!$F:$F,'REGISTRO DE CUOTAS'!$D:$D,$C38,'REGISTRO DE CUOTAS'!$E:$E,$B38) | K38: =IF(E38="","",E38-J38) | L38: Precio anotado como «19 usdt P.M»
B39: 9PM REBEL ORIGINAL | C39: Cristhian Gonzales | D39: Gregory | E39: 70 | F39: 50 | G39: =IF(COUNT(E39:F39)<2,"",E39-F39) | H39: =IF(OR(G39="",E39=""),"",G39/E39) | J39: =SUMIFS('REGISTRO DE CUOTAS'!$F:$F,'REGISTRO DE CUOTAS'!$D:$D,$C39,'REGISTRO DE CUOTAS'!$E:$E,$B39) | K39: =IF(E39="","",E39-J39)
B40: AQUA DI GIO | C40: Ricardo Gomez | D40: Gregory | E40: 16 | F40: 13 | G40: =IF(COUNT(E40:F40)<2,"",E40-F40) | H40: =IF(OR(G40="",E40=""),"",G40/E40) | I40: P.M | J40: =SUMIFS('REGISTRO DE CUOTAS'!$F:$F,'REGISTRO DE CUOTAS'!$D:$D,$C40,'REGISTRO DE CUOTAS'!$E:$E,$B40) | K40: =IF(E40="","",E40-J40) | L40: Precio anotado como «16 P.M»
A41: 22 | B41: SCANDAL | C41: Gabriel Medina | D41: Gregor | E41: 22 | F41: 11 | G41: =IF(COUNT(E41:F41)<2,"",E41-F41) | H41: =IF(OR(G41="",E41=""),"",G41/E41) | J41: =SUMIFS('REGISTRO DE CUOTAS'!$F:$F,'REGISTRO DE CUOTAS'!$D:$D,$C41,'REGISTRO DE CUOTAS'!$E:$E,$B41) | K41: =IF(E41="","",E41-J41)
...

Sheet REGISTRO DE CUOTAS
A1: REGISTRO DE CUOTAS / ABONOS
A2: Hoja reconstruida: las fórmulas de DEUDA en VENTAS ya la buscaban pero no existía. Cargá un abono por fila. CLIENTE (D) y PRODUCTO (E) deben coincidir exactamente con VENTAS.
A3: N° | B3: FECHA | C3: VENDEDOR | D3: CLIENTE | E3: PRODUCTO | F3: MONTO ABONADO ($) | G3: MÉTODO | H3: REFERENCIA | I3: NOTAS

Sheet GASTOS Y COMPRAS
A1: GASTOS Y COMPRAS — ENTRADAS DE COMPRA
A2: El original era texto libre en una sola columna. Aquí cada línea queda tipificada; la columna TEXTO ORIGINAL conserva lo escrito, palabra por palabra.
A3: LOTE | B3: FECHA LOTE | C3: TIPO | D3: DESCRIPCIÓN | E3: MONTO ($) | F3: MONTO Bs | G3: CANAL | H3: TEXTO ORIGINAL | J3: CONTROL POR LOTE — declarado vs. suma de ítems
A4: Lote 19/06/2026 | B4: 46192 | C4: ENCABEZADO | D4: Lote 19/06/2026 | G4: BINANCE | H4: 19.6.2026 TASA BINANCE | J4: LOTE | K4: SUMA ÍTEMS ($) | L4: SUBTOTAL DECLARADO ($) | M4: DIFERENCIA
A5: Lote 19/06/2026 | B5: 46192 | C5: ÍTEM | D5: ARTISTO | E5: 20 | H5: ARTISTO 20$ | J5: Lote 19/06/2026 | K5: =SUMIFS($E:$E,$A:$A,$J5,$C:$C,"ÍTEM") | L5: =SUMIFS($E:$E,$A:$A,$J5,$C:$C,"SUBTOTAL") | M5: =IF(L5=0,"",L5-K5)
A6: Lote 19/06/2026 | B6: 46192 | C6: ÍTEM | D6: CLUB DE NUIT URBAN | E6: 13 | H6: CLUB DE NUIT URBAN 13$ | J6: Lote 26/06/2026 | K6: =SUMIFS($E:$E,$A:$A,$J6,$C:$C,"ÍTEM") | L6: =SUMIFS($E:$E,$A:$A,$J6,$C:$C,"SUBTOTAL") | M6: =IF(L6=0,"",L6-K6)
A7: Lote 19/06/2026 | B7: 46192 | C7: ÍTEM | D7: BAHARARA KING | E7: 20 | H7: BAHARARA KING 20$ | J7: Lote 01/07/2026 | K7: =SUMIFS($E:$E,$A:$A,$J7,$C:$C,"ÍTEM") | L7: =SUMIFS($E:$E,$A:$A,$J7,$C:$C,"SUBTOTAL") | M7: =IF(L7=0,"",L7-K7)
A8: Lote 19/06/2026 | B8: 46192 | C8: ÍTEM | D8: YARA FEM | E8: 13 | H8: YARA FEM 13$ | J8: Lote 08/08/2026 | K8: =SUMIFS($E:$E,$A:$A,$J8,$C:$C,"ÍTEM") | L8: =SUMIFS($E:$E,$A:$A,$J8,$C:$C,"SUBTOTAL") | M8: =IF(L8=0,"",L8-K8)
A9: Lote 19/06/2026 | B9: 46192 | C9: ÍTEM | D9: YARA MOI | E9: 13 | H9: YARA MOI 13$ | J9: Lote 10/08/2026 | K9: =SUMIFS($E:$E,$A:$A,$J9,$C:$C,"ÍTEM") | L9: =SUMIFS($E:$E,$A:$A,$J9,$C:$C,"SUBTOTAL") | M9: =IF(L9=0,"",L9-K9)
A10: Lote 19/06/2026 | B10: 46192 | C10: ÍTEM | D10: KHAMRA QAWA | E10: 20 | H10: KHAMRA QAWA 20 $ | J10: Lote 12/06/2026 | K10: =SUMIFS($E:$E,$A:$A,$J10,$C:$C,"ÍTEM") | L10: =SUMIFS($E:$E,$A:$A,$J10,$C:$C,"SUBTOTAL") | M10: =IF(L10=0,"",L10-K10)
A11: Lote 19/06/2026 | B11: 46192 | C11: SUBTOTAL | D11: Subtotal declarado del lote | E11: 99 | G11: BINANCE | H11: TOTAL 99$ BINANCE | J11: PEDIDO CARACAS LUKA STORE | K11: =SUMIFS($E:$E,$A:$A,$J11,$C:$C,"ÍTEM") | L11: =SUMIFS($E:$E,$A:$A,$J11,$C:$C,"SUBTOTAL") | M11: =IF(L11=0,"",L11-K11)
A12: Lote 26/06/2026 | B12: 46199 | C12: ENCABEZADO | D12: Lote 26/06/2026 | G12: BINANCE | H12: 26.06.2026 TASA BINANCE | J12: Lote 12/08/2026 | K12: =SUMIFS($E:$E,$A:$A,$J12,$C:$C,"ÍTEM") | L12: =SUMIFS($E:$E,$A:$A,$J12,$C:$C,"SUBTOTAL") | M12: =IF(L12=0,"",L12-K12)
A13: Lote 26/06/2026 | B13: 46199 | C13: ÍTEM | D13: CLOUD | E13: 12 | H13: CLOUD 12 $ | J13: TOTAL GENERAL (ítems) | K13: =SUMIF($C:$C,"ÍTEM",$E:$E) | L13: =SUMIF($C:$C,"SUBTOTAL",$E:$E) | M13: =SUM(M5:M12)
A14: Lote 26/06/2026 | B14: 46199 | C14: ÍTEM | D14: GOOD GIRL VERY | E14: 9.5 | H14: GOOD GIRL VERY 9.50$ | J14: Otros gastos ($) — líneas «GASTO» | K14: =SUMIF($C:$C,"GASTO",$E:$E)
A15: Lote 26/06/2026 | B15: 46199 | C15: ÍTEM | D15: ULTRA MALE | E15: 9.5 | H15: ULTRA MALE 9.50$ | J15: Gasto total en Bs registrado | K15: =SUM($F:$F)
A16: Lote 26/06/2026 | B16: 46199 | C16: ÍTEM | D16: SWISS ARMY | E16: 9.5 | H16: SWISS ARMY 9.50$ | J16: TOTAL COMPRAS + GASTOS ($) | K16: =K13+K14
A17: Lote 26/06/2026 | B17: 46199 | C17: ÍTEM | D17: 360 | E17: 9.5 | H17: 360 9.50$
A18: Lote 26/06/2026 | B18: 46199 | C18: ÍTEM | D18: SCANDAL | E18: 9.5 | H18: SCANDAL 9.50$
A19: Lote 26/06/2026 | B19: 46199 | C19: ÍTEM | D19: BAD BOY | E19: 9.5 | H19: BAD BOY 9.50$
A20: Lote 26/06/2026 | B20: 46199 | C20: ÍTEM | D20: TOMMY | E20: 9.5 | H20: TOMMY 9.50$
A21: Lote 26/06/2026 | B21: 46199 | C21: ÍTEM | D21: INVICTUS | E21: 9.5 | H21: INVICTUS 9.50$
A22: Lote 26/06/2026 | B22: 46199 | C22: ÍTEM | D22: 212 VIP | E22: 9.5 | H22: 212 VIP 9.50$
A23: Lote 26/06/2026 | B23: 46199 | C23: ÍTEM | D23: EROS MEN | E23: 9.5 | H23: EROS MEN 9.50$
A24: Lote 26/06/2026 | B24: 46199 | C24: ÍTEM | D24: AGUA DI DIO | E24: 9.5 | H24: AGUA DI DIO 9.50$
A25: Lote 26/06/2026 | B25: 46199 | C25: ÍTEM | D25: HONOR Y GLORY | E25: 17 | H25: HONOR Y GLORY 17$
A26: Lote 26/06/2026 | B26: 46199 | C26: ÍTEM | D26: BAHARARA KING | E26: 20 | H26: BAHARARA KING 20$
A27: Lote 26/06/2026 | B27: 46199 | C27: ÍTEM | D27: UNIVERSE | E27: 20 | H27: UNIVERSE 20$
A28: Lote 26/06/2026 | B28: 46199 | C28: ÍTEM | D28: KHANRAH | E28: 20 | H28: KHANRAH 20$
... A31: Lote 26/06/2026 | B31: 46199 | C31: ÍTEM | D31: LA BOMBA | E31: 17 | H31: LA BOMBA 17$
A32: Lote 26/06/2026 | B32: 46199 | C32: SUBTOTAL | D32: Subtotal declarado del lote | E32: 236 | G32: BINANCE | H32: TOTAL 236$ BINANCE
A33: Lote 01/07/2026 | B33: 46204 | C33: ENCABEZADO | D33: Lote 01/07/2026 | H33: 1.07.2026
A34: Lote 01/07/2026 | B34: 46204 | C34: ÍTEM | D34: 212 MEN | E34: 12 | H34: 212 MEN 12$
A35: Lote 01/07/2026 | B35: 46204 | C35: ÍTEM | D35: HARAMAIN AQUA DUBAI | E35: 18 | H35: HARAMAIN AQUA DUBAI 18$
A36: Lote 01/07/2026 | B36: 46204 | C36: SUBTOTAL | D36: Subtotal declarado del lote | E36: 30 | G36: BINANCE | H36: TOTAL 30$ TASA BINANCE
A37: Lote 08/08/2026 | B37: 46242 | C37: ENCABEZADO | D37: Lote 08/08/2026 | H37: 08/08/2026
A38: Lote 08/08/2026 | B38: 46242 | C38: ÍTEM | D38: FANTASY | E38: 12 | H38: FANTASY 12$
A39: Lote 08/08/2026 | B39: 46242 | C39: ÍTEM | D39: AQUA DI GIO | E39: 12 | H39: AQUA DI GIO 12$
A40: Lote 08/08/2026 | B40: 46242 | C40: ÍTEM | D40: ARIANA GRANDE CLOUD | E40: 12 | H40: ARIANA GRANDE CLOUD 12$
A41: Lote 08/08/2026 | B41: 46242 | C41: ÍTEM | D41: ASAD | E41: 12 | H41: ASAD 12$
A42: Lote 08/08/2026 | B42: 46242 | C42: ÍTEM | D42: YARA ELIXIR | E42: 12 | H42: YARA ELIXIR 12$
...

Sheet PRECIOS PERF ORIGINALES
A1: LISTA DE PRECIOS — PERFUMES ORIGINALES
A2: Los descuentos salen de PARÁMETROS (DESC_TEAM / DESC_REVENDEDOR). Solo se edita el Precio Original.
A3: PRODUCTO | B3: PRECIO ORIGINAL ($) | C3: PRECIO TEAM ($) | D3: PRECIO REVENDEDOR ($)
A4: A.Banderas, black seduction | B4: 50 | C4: =IF(B4="","",ROUND(B4*(1-DESC_TEAM),2)) | D4: =IF(B4="","",ROUND(B4*(1-DESC_REVENDEDOR),2))
A5: A. Banderas, Blue seduction | B5: 50 | C5: =IF(B5="","",ROUND(B5*(1-DESC_TEAM),2)) | D5: =IF(B5="","",ROUND(B5*(1-DESC_REVENDEDOR),2))
A6: A. Banderas, The Golden secret | B6: 50 | C6: =IF(B6="","",ROUND(B6*(1-DESC_TEAM),2)) | D6: =IF(B6="","",ROUND(B6*(1-DESC_REVENDEDOR),2))
A7: A. Banderas the icon | B7: 50 | C7: =IF(B7="","",ROUND(B7*(1-DESC_TEAM),2)) | D7: =IF(B7="","",ROUND(B7*(1-DESC_REVENDEDOR),2))
A8: A. Banderas The Icon (Black) | B8: 50 | C8: =IF(B8="","",ROUND(B8*(1-DESC_TEAM),2)) | D8: =IF(B8="","",ROUND(B8*(1-DESC_REVENDEDOR),2))
A9: Afnan, 9pm | B9: 67 | C9: =IF(B9="","",ROUND(B9*(1-DESC_TEAM),2)) | D9: =IF(B9="","",ROUND(B9*(1-DESC_REVENDEDOR),2))
A10: Ariana grande, CLOUD | B10: 120 | C10: =IF(B10="","",ROUND(B10*(1-DESC_TEAM),2)) | D10: =IF(B10="","",ROUND(B10*(1-DESC_REVENDEDOR),2))
A11: Armaf, club de nuit iconic | B11: 93 | C11: =IF(B11="","",ROUND(B11*(1-DESC_TEAM),2)) | D11: =IF(B11="","",ROUND(B11*(1-DESC_REVENDEDOR),2))
A12: Armaf, Club de nuit intense man | B12: 68 | C12: =IF(B12="","",ROUND(B12*(1-DESC_TEAM),2)) | D12: =IF(B12="","",ROUND(B12*(1-DESC_REVENDEDOR),2))
A13: Armaf, Club de nuit Urban man | B13: 75 | C13: =IF(B13="","",ROUND(B13*(1-DESC_TEAM),2)) | D13: =IF(B13="","",ROUND(B13*(1-DESC_REVENDEDOR),2))
A14: Armaf, club de nuit woman | B14: 66 | C14: =IF(B14="","",ROUND(B14*(1-DESC_TEAM),2)) | D14: =IF(B14="","",ROUND(B14*(1-DESC_REVENDEDOR),2))
A15: Armaf, Odyssey marshmallow | B15: 72 | C15: =IF(B15="","",ROUND(B15*(1-DESC_TEAM),2)) | D15: =IF(B15="","",ROUND(B15*(1-DESC_REVENDEDOR),2))
... A36: Paris Hilton w | B36: 61 | C36: =IF(B36="","",ROUND(B36*(1-DESC_TEAM),2)) | D36: =IF(B36="","",ROUND(B36*(1-DESC_REVENDEDOR),2))

Sheet PRECIOS PERF TOP QUALITY
A1: LISTA DE PRECIOS — TOP QUALITY
A2: Precio = costo + la ganancia definida en PARÁMETROS: +70 % si paga en divisa/USDT, +120 % si paga a tasa BCV. Solo se edita el Costo.
A3: LÍNEA | B3: PRODUCTO | C3: COSTO ($) | D3: PRECIO DIVISA / USDT ($) +70% | E3: PRECIO TASA BCV ($) +120% | G3: RESUMEN (dinámico)
A4: SIN LÍNEA | B4: Cloud | C4: 12 | D4: =IF($C4="","",ROUND($C4*(1+GANANCIA_DIVISA),2)) | E4: =IF($C4="","",ROUND($C4*(1+GANANCIA_BCV),2)) | G4: Productos en catálogo | H4: =COUNTA($B$4:$B$215)
A5: SIN LÍNEA | B5: Good girl very | C5: 9.5 | D5: =IF($C5="","",ROUND($C5*(1+GANANCIA_DIVISA),2)) | E5: =IF($C5="","",ROUND($C5*(1+GANANCIA_BCV),2)) | G5: Con costo cargado | H5: =COUNT($C$4:$C$215)
A6: SIN LÍNEA | B6: Ultramale | C6: 15 | D6: =IF($C6="","",ROUND($C6*(1+GANANCIA_DIVISA),2)) | E6: =IF($C6="","",ROUND($C6*(1+GANANCIA_BCV),2)) | G6: Sin costo (precio en blanco) | H6: =COUNTA($B$4:$B$215)-COUNT($C$4:$C$215)
A7: SIN LÍNEA | B7: Swiss army | C7: 9.5 | D7: =IF($C7="","",ROUND($C7*(1+GANANCIA_DIVISA),2)) | E7: =IF($C7="","",ROUND($C7*(1+GANANCIA_BCV),2)) | G7: Nombres repetidos | H7: =SUMPRODUCT((COUNTIF($B$4:$B$215,$B$4:$B$215)>1)*($B$4:$B$215<>""))
A8: SIN LÍNEA | B8: 360 | C8: 9.5 | D8: =IF($C8="","",ROUND($C8*(1+GANANCIA_DIVISA),2)) | E8: =IF($C8="","",ROUND($C8*(1+GANANCIA_BCV),2)) | G8: Costo promedio ($) | H8: =IFERROR(AVERAGE($C$4:$C$215),"")
A9: SIN LÍNEA | B9: Scandal | C9: 9.5 | D9: =IF($C9="","",ROUND($C9*(1+GANANCIA_DIVISA),2)) | E9: =IF($C9="","",ROUND($C9*(1+GANANCIA_BCV),2)) | G9: Ganancia sobre costo — divisa | H9: =GANANCIA_DIVISA
A10: SIN LÍNEA | B10: Bad boy | C10: 9.5 | D10: =IF($C10="","",ROUND($C10*(1+GANANCIA_DIVISA),2)) | E10: =IF($C10="","",ROUND($C10*(1+GANANCIA_BCV),2)) | G10: Ganancia sobre costo — BCV | H10: =GANANCIA_BCV
A11: SIN LÍNEA | B11: Tommy | C11: 9.5 | D11: =IF($C11="","",ROUND($C11*(1+GANANCIA_DIVISA),2)) | E11: =IF($C11="","",ROUND($C11*(1+GANANCIA_BCV),2))
A12: SIN LÍNEA | B12: Invictus | C12: 9.5 | D12: =IF($C12="","",ROUND($C12*(1+GANANCIA_DIVISA),2)) | E12: =IF($C12="","",ROUND($C12*(1+GANANCIA_BCV),2)) | G12: Amarillo = producto sin costo, su precio queda en blanco (antes mostraba $0,00). Rojo = nombre repetido en el catálogo, a fusionar.
A13: SIN LÍNEA | B13: 212 vip | C13: 9.5 | D13: =IF($C13="","",ROUND($C13*(1+GANANCIA_DIVISA),2)) | E13: =IF($C13="","",ROUND($C13*(1+GANANCIA_BCV),2))
A14: SIN LÍNEA | B14: Eros men | C14: 9.5 | D14: =IF($C14="","",ROUND($C14*(1+GANANCIA_DIVISA),2)) | E14: =IF($C14="","",ROUND($C14*(1+GANANCIA_BCV),2))
A15: SIN LÍNEA | B15: Agua di gio | C15: 9.5 | D15: =IF($C15="","",ROUND($C15*(1+GANANCIA_DIVISA),2)) | E15: =IF($C15="","",ROUND($C15*(1+GANANCIA_BCV),2))
A16: SIN LÍNEA | B16: Honor y glory | C16: 17 | D16: =IF($C16="","",ROUND($C16*(1+GANANCIA_DIVISA),2)) | E16: =IF($C16="","",ROUND($C16*(1+GANANCIA_BCV),2))
A17: SIN LÍNEA | B17: Bharara king | C17: 20 | D17: =IF($C17="","",ROUND($C17*(1+GANANCIA_DIVISA),2)) | E17: =IF($C17="","",ROUND($C17*(1+GANANCIA_BCV),2))
A18: SIN LÍNEA | B18: Universe | C18: 20 | D18: =IF($C18="","",ROUND($C18*(1+GANANCIA_DIVISA),2)) | E18: =IF($C18="","",ROUND($C18*(1+GANANCIA_BCV),2))
A19: SIN LÍNEA | B19: Khamrah | C19: 15 | D19: =IF($C19="","",ROUND($C19*(1+GANANCIA_DIVISA),2)) | E19: =IF($C19="","",ROUND($C19*(1+GANANCIA_BCV),2))
A20: SIN LÍNEA | B20: Club de nuit | C20: 12 | D20: =IF($C20="","",ROUND($C20*(1+GANANCIA_DIVISA),2)) | E20: =IF($C20="","",ROUND($C20*(1+GANANCIA_BCV),2))
A21: SIN LÍNEA | B21: Asad bourbon | C21: 12 | D21: =IF($C21="","",ROUND($C21*(1+GANANCIA_DIVISA),2)) | E21: =IF($C21="","",ROUND($C21*(1+GANANCIA_BCV),2))
A22: SIN LÍNEA | B22: La bomba | C22: 17 | D22: =IF($C22="","",ROUND($C22*(1+GANANCIA_DIVISA),2)) | E22: =IF($C22="","",ROUND($C22*(1+GANANCIA_BCV),2))
A23: LÍNEA ÁRABE | B23: YARA CANDY | D23: =IF($C23="","",ROUND($C23*(1+GANANCIA_DIVISA),2)) | E23: =IF($C23="","",ROUND($C23*(1+GANANCIA_BCV),2))
A24: LÍNEA ÁRABE | B24: YARA ELIXIR | C24: 12 | D24: =IF($C24="","",ROUND($C24*(1+GANANCIA_DIVISA),2)) | E24: =IF($C24="","",ROUND($C24*(1+GANANCIA_BCV),2))
A25: LÍNEA ÁRABE | B25: YARA FEM | D25: =IF($C25="","",ROUND($C25*(1+GANANCIA_DIVISA),2)) | E25: =IF($C25="","",ROUND($C25*(1+GANANCIA_BCV),2))
A26: LÍNEA ÁRABE | B26: YARA TOUS | D26: =IF($C26="","",ROUND($C26*(1+GANANCIA_DIVISA),2)) | E26: =IF($C26="","",ROUND($C26*(1+GANANCIA_BCV),2))
A27: LÍNEA ÁRABE | B27: YARA MOI | D27: =IF($C27="","",ROUND($C27*(1+GANANCIA_DIVISA),2)) | E27: =IF($C27="","",ROUND($C27*(1+GANANCIA_BCV),2))
A28: LÍNEA ÁRABE | B28: ASAD ELIXIR | D28: =IF($C28="","",ROUND($C28*(1+GANANCIA_DIVISA),2)) | E28: =IF($C28="","",ROUND($C28*(1+GANANCIA_BCV),2))
A29: LÍNEA ÁRABE | B29: ASAD | D29: =IF($C29="","",ROUND($C29*(1+GANANCIA_DIVISA),2)) | E29: =IF($C29="","",ROUND($C29*(1+GANANCIA_BCV),2))
A30: LÍNEA ÁRABE | B30: ASAD BOURBON | D30: =IF($C30="","",ROUND($C30*(1+GANANCIA_DIVISA),2)) | E30: =IF($C30="","",ROUND($C30*(1+GANANCIA_BCV),2))
A31: LÍNEA ÁRABE | B31: ASAD ZANZÍBAR | D31: =IF($C31="","",ROUND($C31*(1+GANANCIA_DIVISA),2)) | E31: =IF($C31="","",ROUND($C31*(1+GANANCIA_BCV),2))
A32: LÍNEA ÁRABE | B32: KHAMRA | D32: =IF($C32="","",ROUND($C32*(1+GANANCIA_DIVISA),2)) | E32: =IF($C32="","",ROUND($C32*(1+GANANCIA_BCV),2))
A33: LÍNEA ÁRABE | B33: KHAMRAH DUKHAN | D33: =IF($C33="","",ROUND($C33*(1+GANANCIA_DIVISA),2)) | E33: =IF($C33="","",ROUND($C33*(1+GANANCIA_BCV),2))
A34: LÍNEA ÁRABE | B34: KHAMRAH QAHWA | D34: =IF($C34="","",ROUND($C34*(1+GANANCIA_DIVISA),2)) | E34: =IF($C34="","",ROUND($C34*(1+GANANCIA_BCV),2))
A35: LÍNEA ÁRABE | B35: FAKHAR BLACK | D35: =IF($C35="","",ROUND($C35*(1+GANANCIA_DIVISA),2)) | E35: =IF($C35="","",ROUND($C35*(1+GANANCIA_BCV),2))
A36: LÍNEA ÁRABE | B36: FAKHAR EXTRAIT | D36: =IF($C36="","",ROUND($C36*(1+GANANCIA_DIVISA),2)) | E36: =IF($C36="","",ROUND($C36*(1+GANANCIA_BCV),2))
... A66: LÍNEA ÁRABE | B66: BHARARA NICHE | D66: =IF($C66="","",ROUND($C66*(1+GANANCIA_DIVISA),2)) | E66: =IF($C66="","",ROUND($C66*(1+GANANCIA_BCV),2))
A67: LÍNEA ÁRABE | B67: BHARARA BLUE | C67: 12 | D67: =IF($C67="","",ROUND($C67*(1+GANANCIA_DIVISA),2)) | E67: =IF($C67="","",ROUND($C67*(1+GANANCIA_BCV),2))
A68: LÍNEA ÁRABE | B68: BHARARA ROSE | D68: =IF($C68="","",ROUND($C68*(1+GANANCIA_DIVISA),2)) | E68: =IF($C68="","",ROUND($C68*(1+GANANCIA_BCV),2))
A69: LÍNEA ÁRABE | B69: BHARARA KING SOLEIL | D69: =IF($C69="","",ROUND($C69*(1+GANANCIA_DIVISA),2)) | E69: =IF($C69="","",ROUND($C69*(1+GANANCIA_BCV),2))
...

Sheet CHANGELOG
A1: CHANGELOG — SISTEMA MARFIL v2
A2: Archivo original intacto en 'SISTEMA MARFIL (2).xlsx'. Aquí solo se cambió estructura, formato y fórmulas: ninguna cifra de negocio fue modificada ni inventada.
A3: HOJA | B3: TIPO DE CAMBIO | C3: DETALLE
A4: PARÁMETROS | B4: NUEVO | C4: Hoja nueva con 4 nombres definidos (FACTOR_DIVISA, FACTOR_BCV, DESC_TEAM, DESC_REVENDEDOR) que reemplazan constantes incrustadas en 593 celdas (527 fórmulas con 1,7/2,2 + 66 precios escritos a mano). Los dos primeros se expresan como GANANCIA SOBRE EL COSTO (70 % y 120 %), que es como el negocio los define, en vez de como multiplicador.
A5: CONTROL | B5: ESTRUCTURA | C5: Encabezados duplicados (FECHA x4, MONTO Bs x3, REFERENCIA x3) renombrados a FECHA VENTA / MONTO Bs P1..P3 / FECHA P1..P3 / REFERENCIA P1..P3.
A6: CONTROL | B6: DATOS | C6: 21 celdas numéricas guardadas como texto ('15.679,22', '8.307,00', ...) convertidas a número real. Eran invisibles para SUM.
A7: CONTROL | B7: FÓRMULA | C7: B64 =SUM(F4:F72,I4:I72,L4:L72) sobre rango fijo -> nueva columna TOTAL ABONADO Bs por fila + =SUM(P:P) en el bloque RESUMEN.
A8: CONTROL | B8: FÓRMULA | C8: B67 =COUNTIF(O4:O18,"YA PAGO") solo miraba hasta la fila 18 de las 39 con datos. Hoy daba 10 por casualidad (no había estatus más abajo), pero cualquier venta nueva quedaba fuera del conteo -> =COUNTIF(O:O,"YA PAGO").
A9: CONTROL | B9: DATOS | C9: Textos que no eran montos ni fechas ('12 EFECTIVO', 'listo', 'GM', 'usdt P.M') movidos a la columna NOTAS; la celda numérica queda vacía.
A10: CONTROL | B10: ESTRUCTURA | C10: Filas de totales A64:B69 eliminadas de la zona de datos; reemplazadas por el bloque RESUMEN en S3 con referencias de columna completa.
A11: CONTROL | B11: ESTRUCTURA | C11: Valores sueltos C64=260 y D64=100 preservados en el bloque de revisión (estaban en la fila de totales bajo VENDEDOR y PRODUCTO).
A12: CONTROL | B12: FORMATO | C12: Fechas unificadas a dd/mm/yyyy (el original mezclaba d/m/yy, dd-mm-yy, d/m/yyyy y dd/mm/yyyy).
A13: CONTROL | B13: FORMATO | C13: Columna E con formato moneda $, columnas de pago con formato Bs, validación de lista en ESTATUS y semáforo por estado.
A14: CONTROL | B14: LIMPIEZA | C14: 999 filas y ninguna columna vacías descartadas: la hoja declaraba A1:O1038 con datos solo hasta la fila 39.
... A43: PRECIOS PERF TOP QUALITY | B43: FORMATO | C43: Encabezados fuera de A1 (estaban en la fila 3 bajo un título fusionado A1:D2) normalizados; tabla 'PreciosTopQuality' con autofiltro y paneles congelados.
