Workbook

Sheet CONTROL
F1: PAGO 1 | I1: PAGO 2 | L1: PAGO 3
A3: FECHA | B3: CLIENTE | C3: VENDEDOR | D3: PRODUCTO | E3: PRECIO TOTAL ($) | F3: MONTO Bs | G3: FECHA | H3: REFERENCIA | I3: MONTO Bs | J3: FECHA | K3: REFERENCIA | L3: MONTO Bs | M3: FECHA | N3: REFERENCIA | O3: ESTATUS
A4: 46200 | B4: Cristhian | C4: Gregory | D4: Very Good Girl | E4: 24 | F4: 7466.56 | G4: 46200 | H4: 5863 | I4: 7835.67 | J4: 46207 | K4: 9442 | O4: YA PAGO
A5: 46200 | B5: Amarista | C5: Gregory | D5: Khamrah Qahwa | E5: 42 | F5: 13066.48 | G5: 46200 | H5: 6585 | I5: 14903.56 | J5: 46214 | K5: 5675 | O5: YA PAGO
A6: 46201 | B6: Ángel | C6: Gregory | D6: Bharara King | E6: 42 | F6: 13066.48 | G6: 46201 | H6: 5135 | I6: 15.679,22 | J6: 46235 | K6: 7366 | O6: YA PAGO
A7: 46202 | B7: Ricardo | C7: Gregory | D7: Universe | E7: 42 | F7: 11823 | G7: 46202 | H7: 9373 | I7: 8730 | J7: 46219 | K7: 1008 | L7: 8.307,00 | M7: 46239 | N7: 542 | O7: YA PAGO
A8: 46206 | B8: Norelvis | C8: Gregory | D8: Cloud | E8: 30 | F8: 9794.59 | G8: 46206 | H8: 8447 | I8: 10645.4 | J8: 46215 | K8: 4494 | O8: YA PAGO
A9: 46207 | B9: Anderson | C9: Gregory | D9: 212 Vip | E9: 22 | F9: 4580 | G9: 46207 | H9: 172 | I9: 5100 | J9: 46218 | K9: 2830 | L9: 5.910,00 | M9: 46231 | N9: 5001 | O9: YA PAGO
A10: 46207 | B10: Marbella | C10: Gregory | D10: Yara Moi | E10: 30 | F10: 13341 | G10: 46207 | H10: 1469 | I10: 7420 | J10: 46228 | K10: 6675 | M10: listo | O10: YA PAGO
A11: 46207 | B11: Polanco | C11: Gregory | D11: Club de Nuit | E11: 30 | F11: 9794.59 | G11: 46207 | H11: 9023 | I11: 11068.22 | J11: 46228 | K11: 2736 | M11: listo | O11: YA PAGO
A12: 46214 | B12: Polanco | C12: Gregory | D12: Honor y Glory | E12: 35 | F12: 14193.87 | G12: 46214 | H12: 5460 | I12: 11.199,45 | J12: 46236 | K12: 2165
A13: 46215 | B13: Llovera | C13: Gregory | D13: Eros Men | E13: 24 | F13: 17000 | G13: 46215 | H13: 1911 | O13: YA PAGO
A14: 46218 | B14: Belisario | C14: Gregory | D14: Club de Nuit Urban | E14: 30 | F14: 10886.21 | G14: 46218 | H14: 7099 | O14: PENDIENTE
A15: 46219 | B15: Fernanda | C15: Gregory | D15: Yara Fem | E15: 30 | F15: 14549.02 | G15: 46219 | H15: 7014 | I15: 3.733,15 | J15: 46236 | K15: 9323 | O15: PENDIENTE
A16: 46220 | B16: Cristhian | C16: Gregory | D16: Aqua Dubai | E16: 34 | F16: 10645.4 | G16: 46213 | H16: 8770 | I16: 10987.18 | J16: 46220 | K16: 546 | L16: 2951.53 | M16: 46227 | N16: 9686 | O16: YA PAGO
A17: 46192 | B17: Ivana | C17: Gregory | D17: La Bomba | E17: 30 | O17: PENDIENTE (SIN ABONOS)
A18: 46199 | B18: Reinel | C18: Hidelberg | D18: 212 NYC | E18: 24 | F18: 18.183,00 | G18: 46244 | H18: 4795
A19: 46220 | B19: mirleidy | C19: Gregory | D19: 360 | E19: 12 MY | F19: 12 EFECTIVO | G19: 46236
A20: 46220 | B20: mirleidy | C20: Gregory | D20: ASAD BORBOM | E20: 16 MY | F20: 16 EFECTIVO | G20: 46236
A21: 46232 | B21: Polanco | C21: Gregory | D21: TOMMY | E21: 24 | F21: 8.854,58 | G21: 46231 | H21: 1826 | I21: 8.985,44 | J21: 46237 | K21: 5170
A22: 46232 | B22: Belisario | C22: Gregory | D22: BAD BOY | E22: 24
A23: 46233 | B23: Anderson | C23: Gregory | D23: AQUA DI GIO | E23: 22 | F23: 5.400,00 | G23: 46250 | H23: 2265
A24: 46236 | B24: adolfito | C24: Gregory | D24: SCANDAL | E24: 22 | F24: 8.212,93 | G24: 46236 | H24: 1103
A25: 46236 | B25: rafael | C25: Gregory | D25: INVICTUS | E25: 22 | F25: 5.226,34 | G25: 46236 | H25: 666 | I25: 5.398,00 | J25: 46249 | K25: 8343
A26: 46061 | B26: Ricardo | C26: Gregory | D26: AQUA DI GIO | E26: 24
A27: 46061 | B27: melany | C27: Gregory | D27: CLOUD | E27: 24
A28: 46061 | B28: gregor | C28: Gregor | D28: BHARARA BLUE | E28: 18 GM
A29: 46061 | B29: hidelberg | C29: Hidelberg | D29: TOMMY | E29: 12 GM
A30: 46061 | B30: Juan herrade | C30: Gregor | D30: Sauvage Dior | E30: 22
A31: 46061 | B31: Juan herrade | C31: Gregor | D31: Victorinox swis army | E31: 22
A32: 46061 | B32: Ricardo palacios | C32: Gregor | D32: Eros Flame | E32: 22
A33: 46061 | B33: Ricardo palacios | C33: Gregor | D33: Mandarin Sky | E33: 22
A34: 46244 | B34: jeferson mejias | C34: Hidelberg | D34: BHARARA KING | E34: 42
A35: 46245 | B35: apostol | C35: Gregory | D35: Sauvage Dior | E35: 24 | F35: 9.252,86 | G35: 46249 | H35: 7526
A36: 46244 | B36: hade mirleidy | C36: Gregor | D36: YARA ELIXIR | E36: 24
A37: 46244 | B37: luis sequera | C37: Gregor | D37: Mandarin Sky | E37: 31
A38: 46246 | B38: ricardo gomez | C38: Gregory | D38: CLUD DE NUIT INTENSE | E38: 19 usdt P.M | F38: 8.356,00 | G38: 46246 | H38: 4657
A39: 46247 | B39: cristhian gonzales | C39: Gregory | D39: 9PM REBEL ORIGINAL | E39: 70
A64: Total en Bs | B64: =SUM(F4:F72, I4:I72, L4:L72) -> 229848.76 | C64: 260 | D64: 100
A65: Total Divisas Pagadas ($) | B65: 306
...

Sheet GASTOS Y COMPRAS 
A1: ENTRADAS DE COMPRA
A3: 19.6.2026 TASA BINANCE
A4: ARTISTO 20$
A5: CLUB DE NUIT URBAN 13$
A6: BAHARARA KING 20$
A7: YARA FEM 13$
A8: YARA MOI 13$
A9: KHAMRA QAWA 20 $
A10: TOTAL 99$ BINANCE
A12: 26.06.2026 TASA BINANCE
A13: CLOUD 12 $
A14: GOOD GIRL VERY 9.50$
... A38: TOTAL 30$ TASA BINANCE
A40: 46242
A41: FANTASY 12$
A42: AQUA DI GIO 12$
A43: ARIANA GRANDE CLOUD 12$
A44: ASAD 12$
A45: YARA ELIXIR 12$
A46: 212 VIP MEN 12$
A47: EROS FLAME 12$
A48: LE LABO SANTAL 33 12$
A49: SAUVAGE DIOR 12$
A50: TOMY MEN 12$
A51: ASAD BOURBOND 12$
A52: BHARARA BLUE 18$
... A55: TASA BINANCE 176$
A57: 46244
A58: DECANST 1$
A59: MANDARIN SKY 15$
A60: MANDARIN SKY 15$
A61: SAUVAGE DIOR 13$
A62: SAUVAGE DIOR 13$
A63: SAUVAGE DIOR 13$
A64: SAUVAGE DIOR 13$
A65: ACQUA DI GIO 13$
A66: ACQUA DI GIO 13$
A67: TASA BINANCE 109$
A69: 46185
A70: CLUD DE NUIT INTENSE 15$
...

Sheet VENTAS
C2: Registro de Ventas
C4: Producto | D4: Cliente | E4: Vendedor | F4: Precio Venta ($) | G4: Costo ($) | H4: Ganancia ($) | I4: Moneda | J4: Deuda ($) | L4: Métrica | M4: Valor
B5: 1 | C5: Yara Fem | D5: Fernanda | E5: Gregory | F5: 30 | G5: 13 | H5: =F5-G5 -> 17 | I5: BCV | J5: =IF(ISBLANK(C5), "", F5 - SUMIFS('REGISTRO DE CUOTAS '!F:F, 'REGISTRO DE CUOTAS '!D:D, D5, 'REGISTRO DE CUOTAS '!E:E, C5)) -> #N/A | L5: Total Ventas | M5: =SUM(F5:F997) -> 1036.5
B6: 2 | C6: Bharara King | D6: Ángel | E6: Gregory | F6: 42 | G6: 20 | H6: =F6-G6 -> 22 | I6: BCV | J6: =IF(ISBLANK(C6), "", F6 - SUMIFS('REGISTRO DE CUOTAS '!F:F, 'REGISTRO DE CUOTAS '!D:D, D6, 'REGISTRO DE CUOTAS '!E:E, C6)) -> #N/A | L6: Costo Total | M6: =SUM(G5:G997) -> 632
B7: 3 | C7: Khamarah Qahwa | D7: Amarista | E7: Gregory | F7: 42 | G7: 20 | H7: =F7-G7 -> 22 | I7: BCV | J7: =IF(ISBLANK(C7), "", F7 - SUMIFS('REGISTRO DE CUOTAS '!F:F, 'REGISTRO DE CUOTAS '!D:D, D7, 'REGISTRO DE CUOTAS '!E:E, C7)) -> #N/A | L7: Ganancia Total | M7: =SUM(H5:H997) -> 194.5
B8: 4 | C8: Universe | D8: Ricardo | E8: Gregory | F8: 42 | G8: 20 | H8: =F8-G8 -> 22 | I8: BCV | J8: =IF(ISBLANK(C8), "", F8 - SUMIFS('REGISTRO DE CUOTAS '!F:F, 'REGISTRO DE CUOTAS '!D:D, D8, 'REGISTRO DE CUOTAS '!E:E, C8)) -> #N/A | L8: Total por Cobrar | M8: =SUM(J5:J997) -> #N/A
B9: 5 | C9: Club de Nuit Urban Elixir | D9: Belisario | E9: Gregory | F9: 30 | G9: 13 | H9: =F9-G9 -> 17 | I9: BCV | J9: =IF(ISBLANK(C9), "", F9 - SUMIFS('REGISTRO DE CUOTAS '!F:F, 'REGISTRO DE CUOTAS '!D:D, D9, 'REGISTRO DE CUOTAS '!E:E, C9)) -> #N/A
B10: 6 | C10: Yara Moi | D10: Marbella | E10: Gregory | F10: 30 | G10: 13 | H10: =F10-G10 -> 17 | I10: BCV | J10: =IF(ISBLANK(C10), "", F10 - SUMIFS('REGISTRO DE CUOTAS '!F:F, 'REGISTRO DE CUOTAS '!D:D, D10, 'REGISTRO DE CUOTAS '!E:E, C10)) -> #N/A
B11: 7 | C11: Very Good Grul | D11: Cristihan | E11: Gregory | F11: 24 | G11: 9.5 | H11: =F11-G11 -> 14.5 | I11: BCV | J11: =IF(ISBLANK(C11), "", F11 - SUMIFS('REGISTRO DE CUOTAS '!F:F, 'REGISTRO DE CUOTAS '!D:D, D11, 'REGISTRO DE CUOTAS '!E:E, C11)) -> #N/A
B12: 8 | C12: Honor y glory | D12: Polanco | E12: Gregory | F12: 35 | G12: 12 | H12: =F12-G12 -> 23 | I12: BCV | J12: =IF(ISBLANK(C12), "", F12 - SUMIFS('REGISTRO DE CUOTAS '!F:F, 'REGISTRO DE CUOTAS '!D:D, D12, 'REGISTRO DE CUOTAS '!E:E, C12)) -> #N/A
B13: 9 | C13: cloud | D13: Norelvis | E13: Gregory | F13: 30 | G13: 12 | H13: =F13-G13 -> 18 | I13: BCV | J13: =IF(ISBLANK(C13), "", F13 - SUMIFS('REGISTRO DE CUOTAS '!F:F, 'REGISTRO DE CUOTAS '!D:D, D13, 'REGISTRO DE CUOTAS '!E:E, C13)) -> #N/A
C14: la bomba | D14: Ivana | E14: Gregory | F14: 30 | G14: 17 | H14: =F14-G14 -> 13 | I14: BCV | J14: =IF(ISBLANK(C14), "", F14 - SUMIFS('REGISTRO DE CUOTAS '!F:F, 'REGISTRO DE CUOTAS '!D:D, D14, 'REGISTRO DE CUOTAS '!E:E, C14)) -> #N/A
C15: Aqua Dubai | D15: Cristhian | E15: Gregory | F15: 34 | G15: 18 | H15: =F15-G15 -> 16 | I15: BCV | J15: =IF(ISBLANK(C15), "", F15 - SUMIFS('REGISTRO DE CUOTAS '!F:F, 'REGISTRO DE CUOTAS '!D:D, D15, 'REGISTRO DE CUOTAS '!E:E, C15)) -> #N/A
B16: 10 | C16: 212Vip | D16: Anderson | E16: Gregory | F16: 9.5 | G16: 22 | H16: =F16-G16 -> -12.5 | I16: BCV | J16: =IF(ISBLANK(C16), "", F16 - SUMIFS('REGISTRO DE CUOTAS '!F:F, 'REGISTRO DE CUOTAS '!D:D, D16, 'REGISTRO DE CUOTAS '!E:E, C16)) -> #N/A
C17: Club de Nuit | D17: Polanco | E17: Gregory | F17: 30 | G17: 51 | H17: =F17-G17 -> -21 | I17: BCV | J17: =IF(ISBLANK(C17), "", F17 - SUMIFS('REGISTRO DE CUOTAS '!F:F, 'REGISTRO DE CUOTAS '!D:D, D17, 'REGISTRO DE CUOTAS '!E:E, C17)) -> #N/A
B18: 11 | C18: 212 NYC | D18: Reinel | E18: Hidelberg | F18: 24 | G18: 12 | H18: =F18-G18 -> 12 | I18: BCV | J18: =IF(ISBLANK(C18), "", F18 - SUMIFS('REGISTRO DE CUOTAS '!F:F, 'REGISTRO DE CUOTAS '!D:D, D18, 'REGISTRO DE CUOTAS '!E:E, C18)) -> #N/A
B19: 12 | C19: EROS MEN VERSACHE | D19: llovera | E19: Gregory | F19: 24 | G19: 9.5 | H19: =F19-G19 -> 14.5
B20: 13 | C20: 360 | D20: mirleidy | E20: Gregory | F20: 12 | G20: 9.5
C21: ASAD BORBOM | D21: mirleidy | E21: Gregory | F21: 16 | G21: 13
C22: TOMMY | D22: Polanco | E22: Gregory | F22: 24 | G22: 11
C23: BAD BOY | D23: Belisario | E23: Gregory | F23: 24 | G23: 9.5
C24: AQUA DI GIO | D24: Anderson | E24: Gregory | F24: 22 | G24: 9.5
B25: 14 | C25: SCANDAL | D25: Adolfito | E25: Gregory | F25: 22 | G25: 9.5
B26: 15 | C26: INVICTUS | D26: rafael | E26: Gregory | F26: 22 | G26: 9.5
C27: AQUA DI GIO | D27: ricardo | E27: Gregory | F27: 24 | G27: 12
B28: 16 | C28: CLOUD | D28: melany | E28: Gregory | F28: 24 | G28: 12
C29: BHARARA BLUE | D29: gregor | E29: Gregor | F29: 18.GM | G29: 18
C30: TOMMY | D30: hidelberg | E30: Hidelberg | F30: 12.GM | G30: 12
B31: 17 | C31: Sauvage Dior | D31: Juan herrade | E31: Gregory | F31: 22 | G31: 12
C32: Victorinox swis army | D32: Juan herrade | E32: Gregory | F32: 22 | G32: 9.5
B33: 18 | C33: Eros Flame | D33: Ricardo palacios | E33: Gregor | F33: 22 | G33: 12
C34: Mandarin Sky | D34: Ricardo palacios | E34: Gregor | F34: 22 | G34: 15
B35: 19 | C35: BHARARA KING | D35: jeferson mejias | E35: Hidelberg | F35: 42 | G35: 20
B36: 20 | C36: Sauvage Dior | D36: apostol | E36: gregory | F36: 24 | G36: 12
C37: YARA ELIXIR | D37: hade mirleidy | E37: gregor | F37: 24 | G37: 12
B38: 21 | C38: Mandarin Sky | D38: luis sequera | E38: gregor | F38: 32 | G38: 15
C39: CLUD DE NUIT INTENSE | D39: ricardo gomez | E39: gregory | F39: 19 usdt P.M | G39: 15
C40: 9PM REBEL ORIGINAL | D40: cristhian gonzales | E40: gregory | F40: 70 | G40: 50
C41: AQUA DI GIO | D41: ricardo gomez | E41: gregory | F41: 16 P.M | G41: 13
B42: 22 | C42: SCANDAL | D42: gabriel medina | E42: Gregor | F42: 22 | G42: 11
...

Sheet PRECIOS PERF ORIGINALES
A1: Producto | B1: Precio Original | C1: Para el team (-25%) | D1: Revendedores (-15%)
A2: A.Banderas, black seduction | B2: 50 | C2: 37.5 | D2: 42.5
A3: A. Banderas, Blue seduction | B3: 50 | C3: 37.5 | D3: 42.5
A4: A. Banderas, The Golden secret | B4: 50 | C4: 37.5 | D4: 42.5
A5: A. Banderas the icon | B5: 50 | C5: 37.5 | D5: 42.5
A6: A. Banderas The Icon (Black) | B6: 50 | C6: 37.5 | D6: 42.5
A7: Afnan, 9pm | B7: 67 | C7: 50.25 | D7: 56.95
A8: Ariana grande, CLOUD | B8: 120 | C8: 90 | D8: 102
A9: Armaf, club de nuit iconic | B9: 93 | C9: 69.75 | D9: 79.05
A10: Armaf, Club de nuit intense man | B10: 68 | C10: 51 | D10: 57.8
A11: Armaf, Club de nuit Urban man | B11: 75 | C11: 56.25 | D11: 63.75
A12: Armaf, club de nuit woman | B12: 66 | C12: 49.5 | D12: 56.1
A13: Armaf, Odyssey marshmallow | B13: 72 | C13: 54 | D13: 61.2
... A34: Paris Hilton w | B34: 61 | C34: 45.75 | D34: 51.85

Sheet PRECIOS PERF TOP QUALITY 
A1: Lista de precios Nueva
A3: Producto | B3: Costo ($) | C3: Precio (Divisa o tasa USDT) | D3: Precio tasa BCV
A4: Cloud | B4: 12 | C4: =B4 * 1.7 -> 20.4 | D4: =B4 * 2.2 -> 26.4
A5: Good girl very | B5: 9.5 | C5: =B5 * 1.7 -> 16.15 | D5: =B5 * 2.2 -> 20.9
A6: Ultramale | B6: 15 | C6: =B6 * 1.7 -> 25.5 | D6: =B6 * 2.2 -> 33
A7: Swiss army | B7: 9.5 | C7: =B7 * 1.7 -> 16.15 | D7: =B7 * 2.2 -> 20.9
A8: 360 | B8: 9.5 | C8: =B8 * 1.7 -> 16.15 | D8: =B8 * 2.2 -> 20.9
A9: Scandal | B9: 9.5 | C9: =B9 * 1.7 -> 16.15 | D9: =B9 * 2.2 -> 20.9
A10: Bad boy | B10: 9.5 | C10: =B10 * 1.7 -> 16.15 | D10: =B10 * 2.2 -> 20.9
A11: Tommy | B11: 9.5 | C11: =B11 * 1.7 -> 16.15 | D11: =B11 * 2.2 -> 20.9
A12: Invictus | B12: 9.5 | C12: =B12 * 1.7 -> 16.15 | D12: =B12 * 2.2 -> 20.9
A13: 212 vip | B13: 9.5 | C13: =B13 * 1.7 -> 16.15 | D13: =B13 * 2.2 -> 20.9
A14: Eros men | B14: 9.5 | C14: =B14 * 1.7 -> 16.15 | D14: =B14 * 2.2 -> 20.9
A15: Agua di gio | B15: 9.5 | C15: =B15 * 1.7 -> 16.15 | D15: =B15 * 2.2 -> 20.9
A16: Honor y glory | B16: 17 | C16: =B16 * 1.7 -> 28.9 | D16: =B16 * 2.2 -> 37.4
A17: Bharara king | B17: 20 | C17: =B17 * 1.7 -> 34 | D17: =B17 * 2.2 -> 44
A18: Universe | B18: 20 | C18: =B18 * 1.7 -> 34 | D18: =B18 * 2.2 -> 44
A19: Khamrah | B19: 15 | C19: =B19 * 1.7 -> 25.5 | D19: =B19 * 2.2 -> 33
A20: Club de nuit | B20: 12 | C20: =B20 * 1.7 -> 20.4 | D20: =B20 * 2.2 -> 26.4
... A22: La bomba | B22: 17 | C22: =B22 * 1.7 -> 28.9 | D22: =B22 * 2.2 -> 37.4
A23: LINEA ARABE | C23: =B23 * 1.7 -> 0 | D23: =B23 * 2.2 -> 0
A24: YARA CANDY | C24: =B24 * 1.7 -> 0 | D24: =B24 * 2.2 -> 0
A25: YARA ELIXIR | B25: 12 | C25: =B25 * 1.7 -> 20.4 | D25: =B25 * 2.2 -> 26.4
A26: YARA FEM | C26: =B26 * 1.7 -> 0 | D26: =B26 * 2.2 -> 0
A27: YARA TOUS | C27: =B27 * 1.7 -> 0 | D27: =B27 * 2.2 -> 0
A28: YARA MOI | C28: =B28 * 1.7 -> 0 | D28: =B28 * 2.2 -> 0
A29: ASAD ELIXIR | C29: =B29 * 1.7 -> 0 | D29: =B29 * 2.2 -> 0
A30: ASAD | C30: =B30 * 1.7 -> 0 | D30: =B30 * 2.2 -> 0
A31: ASAD BOURBON | C31: =B31 * 1.7 -> 0 | D31: =B31 * 2.2 -> 0
A32: ASAD ZANZÍBAR | C32: =B32 * 1.7 -> 0 | D32: =B32 * 2.2 -> 0
A33: KHAMRA | C33: =B33 * 1.7 -> 0 | D33: =B33 * 2.2 -> 0
A34: KHAMRAH DUKHAN | C34: =B34 * 1.7 -> 0 | D34: =B34 * 2.2 -> 0
A35: KHAMRAH QAHWA | C35: =B35 * 1.7 -> 0 | D35: =B35 * 2.2 -> 0
A36: FAKHAR BLACK | C36: =B36 * 1.7 -> 0 | D36: =B36 * 2.2 -> 0
A37: FAKHAR EXTRAIT | C37: =B37 * 1.7 -> 0 | D37: =B37 * 2.2 -> 0
... A67: BHARARA NICHE | C67: =B67 * 1.7 -> 0 | D67: =B67 * 2.2 -> 0
A68: BHARARA BLUE | B68: 12 | C68: =B68 * 1.7 -> 20.4 | D68: =B68 * 2.2 -> 26.4
A69: BHARARA ROSE | C69: =B69 * 1.7 -> 0 | D69: =B69 * 2.2 -> 0
A70: BHARARA KING SOLEIL | C70: =B70 * 1.7 -> 0 | D70: =B70 * 2.2 -> 0
A71: BHARARA SCARLET | C71: =B71 * 1.7 -> 0 | D71: =B71 * 2.2 -> 0
...
